Traceback (most recent call last):
  File "/home/manish.mourya001/anaconda3/envs/cs231n/lib/python3.6/site-packages/tensorflow/python/pywrap_tensorflow.py", line 58, in <module>
    from tensorflow.python.pywrap_tensorflow_internal import *
  File "/home/manish.mourya001/anaconda3/envs/cs231n/lib/python3.6/site-packages/tensorflow/python/pywrap_tensorflow_internal.py", line 28, in <module>
    _pywrap_tensorflow_internal = swig_import_helper()
  File "/home/manish.mourya001/anaconda3/envs/cs231n/lib/python3.6/site-packages/tensorflow/python/pywrap_tensorflow_internal.py", line 24, in swig_import_helper
    _mod = imp.load_module('_pywrap_tensorflow_internal', fp, pathname, description)
  File "/home/manish.mourya001/anaconda3/envs/cs231n/lib/python3.6/imp.py", line 243, in load_module
    return load_dynamic(name, filename, file)
  File "/home/manish.mourya001/anaconda3/envs/cs231n/lib/python3.6/imp.py", line 343, in load_dynamic
    return _load(spec)
ImportError: libcublas.so.10.0: cannot open shared object file: No such file or directory

During handling of the above exception, another exception occurred:

Traceback (most recent call last):
  File "t_flow.py", line 2, in <module>
    import tensorflow as tf
  File "/home/manish.mourya001/anaconda3/envs/cs231n/lib/python3.6/site-packages/tensorflow/__init__.py", line 24, in <module>
    from tensorflow.python import pywrap_tensorflow  # pylint: disable=unused-import
  File "/home/manish.mourya001/anaconda3/envs/cs231n/lib/python3.6/site-packages/tensorflow/python/__init__.py", line 49, in <module>
    from tensorflow.python import pywrap_tensorflow
  File "/home/manish.mourya001/anaconda3/envs/cs231n/lib/python3.6/site-packages/tensorflow/python/pywrap_tensorflow.py", line 74, in <module>
    raise ImportError(msg)
ImportError: Traceback (most recent call last):
  File "/home/manish.mourya001/anaconda3/envs/cs231n/lib/python3.6/site-packages/tensorflow/python/pywrap_tensorflow.py", line 58, in <module>
    from tensorflow.python.pywrap_tensorflow_internal import *
  File "/home/manish.mourya001/anaconda3/envs/cs231n/lib/python3.6/site-packages/tensorflow/python/pywrap_tensorflow_internal.py", line 28, in <module>
    _pywrap_tensorflow_internal = swig_import_helper()
  File "/home/manish.mourya001/anaconda3/envs/cs231n/lib/python3.6/site-packages/tensorflow/python/pywrap_tensorflow_internal.py", line 24, in swig_import_helper
    _mod = imp.load_module('_pywrap_tensorflow_internal', fp, pathname, description)
  File "/home/manish.mourya001/anaconda3/envs/cs231n/lib/python3.6/imp.py", line 243, in load_module
    return load_dynamic(name, filename, file)
  File "/home/manish.mourya001/anaconda3/envs/cs231n/lib/python3.6/imp.py", line 343, in load_dynamic
    return _load(spec)
ImportError: libcublas.so.10.0: cannot open shared object file: No such file or directory


Failed to load the native TensorFlow runtime.

See https://www.tensorflow.org/install/errors

for some common reasons and solutions.  Include the entire stack trace
above this error message when asking for help.
DeprecationWarning: 'source deactivate' is deprecated. Use 'conda deactivate'.
